Workbook

Sheet config
A1: Giorno | B1: OvercapPercent | C1: OvercapPenalty
A2: Lun | B2: 0.25 | C2: 1
A3: Mar | B3: 0.25 | C3: 1
A4: Mer | B4: 0.25 | C4: 1
A5: Gio | B5: 0.25 | C5: 1
A6: Ven | B6: 0.25 | C6: 1
A7: Sab | B7: 0.05 | C7: 1.2
A8: Dom | B8: 0 | C8: 1.8

Sheet Requisiti_dc
A1: fasce | B1: Lun | C1: Mar | D1: Mer | E1: Gio | F1: Ven | G1: Sab | H1: Dom
A2: 00:15-00:30 | B2: 0 | C2: 0 | D2: 0 | E2: 0 | F2: 0 | G2: 0 | H2: 0
A3: 00:30-00:45 | B3: 0 | C3: 0 | D3: 0 | E3: 0 | F3: 0 | G3: 0 | H3: 0
A4: 00:45-01:00 | B4: 0 | C4: 0 | D4: 0 | E4: 0 | F4: 0 | G4: 0 | H4: 0
A5: 01:00-01:15 | B5: 0 | C5: 0 | D5: 0 | E5: 0 | F5: 0 | G5: 0 | H5: 0
A6: 01:15-01:30 | B6: 0 | C6: 0 | D6: 0 | E6: 0 | F6: 0 | G6: 0 | H6: 0
A7: 01:30-01:45 | B7: 0 | C7: 0 | D7: 0 | E7: 0 | F7: 0 | G7: 0 | H7: 0
A8: 01:45-02:00 | B8: 0 | C8: 0 | D8: 0 | E8: 0 | F8: 0 | G8: 0 | H8: 0
A9: 02:00-02:15 | B9: 0 | C9: 0 | D9: 0 | E9: 0 | F9: 0 | G9: 0 | H9: 0
A10: 02:15-02:30 | B10: 0 | C10: 0 | D10: 0 | E10: 0 | F10: 0 | G10: 0 | H10: 0
A11: 02:30-02:45 | B11: 0 | C11: 0 | D11: 0 | E11: 0 | F11: 0 | G11: 0 | H11: 0
A12: 02:45-03:00 | B12: 0 | C12: 0 | D12: 0 | E12: 0 | F12: 0 | G12: 0 | H12: 0
A13: 03:00-03:15 | B13: 0 | C13: 0 | D13: 0 | E13: 0 | F13: 0 | G13: 0 | H13: 0
... A96: 23:45-00:00 | B96: 0 | C96: 0 | D96: 0 | E96: 0 | F96: 0 | G96: 0 | H96: 0

Sheet Requisiti_ps
A1: fasce | B1: Lun | C1: Mar | D1: Mer | E1: Gio | F1: Ven | G1: Sab | H1: Dom
A2: 00:15-00:30 | B2: 0 | C2: 0 | D2: 0 | E2: 0 | F2: 0 | G2: 0 | H2: 0
A3: 00:30-00:45 | B3: 0 | C3: 0 | D3: 0 | E3: 0 | F3: 0 | G3: 0 | H3: 0
A4: 00:45-01:00 | B4: 0 | C4: 0 | D4: 0 | E4: 0 | F4: 0 | G4: 0 | H4: 0
A5: 01:00-01:15 | B5: 0 | C5: 0 | D5: 0 | E5: 0 | F5: 0 | G5: 0 | H5: 0
A6: 01:15-01:30 | B6: 0 | C6: 0 | D6: 0 | E6: 0 | F6: 0 | G6: 0 | H6: 0
A7: 01:30-01:45 | B7: 0 | C7: 0 | D7: 0 | E7: 0 | F7: 0 | G7: 0 | H7: 0
A8: 01:45-02:00 | B8: 0 | C8: 0 | D8: 0 | E8: 0 | F8: 0 | G8: 0 | H8: 0
A9: 02:00-02:15 | B9: 0 | C9: 0 | D9: 0 | E9: 0 | F9: 0 | G9: 0 | H9: 0
A10: 02:15-02:30 | B10: 0 | C10: 0 | D10: 0 | E10: 0 | F10: 0 | G10: 0 | H10: 0
A11: 02:30-02:45 | B11: 0 | C11: 0 | D11: 0 | E11: 0 | F11: 0 | G11: 0 | H11: 0
A12: 02:45-03:00 | B12: 0 | C12: 0 | D12: 0 | E12: 0 | F12: 0 | G12: 0 | H12: 0
A13: 03:00-03:15 | B13: 0 | C13: 0 | D13: 0 | E13: 0 | F13: 0 | G13: 0 | H13: 0
... A96: 23:45-00:00 | B96: 0 | C96: 0 | D96: 0 | E96: 0 | F96: 0 | G96: 0 | H96: 0

Sheet Requisiti_cmb
A1: fasce | B1: Lun | C1: Mar | D1: Mer | E1: Gio | F1: Ven | G1: Sab | H1: Dom
A2: 00:15-00:30 | B2: 0 | C2: 0 | D2: 0 | E2: 0 | F2: 0 | G2: 0 | H2: 0
A3: 00:30-00:45 | B3: 0 | C3: 0 | D3: 0 | E3: 0 | F3: 0 | G3: 0 | H3: 0
A4: 00:45-01:00 | B4: 0 | C4: 0 | D4: 0 | E4: 0 | F4: 0 | G4: 0 | H4: 0
A5: 01:00-01:15 | B5: 0 | C5: 0 | D5: 0 | E5: 0 | F5: 0 | G5: 0 | H5: 0
A6: 01:15-01:30 | B6: 0 | C6: 0 | D6: 0 | E6: 0 | F6: 0 | G6: 0 | H6: 0
A7: 01:30-01:45 | B7: 0 | C7: 0 | D7: 0 | E7: 0 | F7: 0 | G7: 0 | H7: 0
A8: 01:45-02:00 | B8: 0 | C8: 0 | D8: 0 | E8: 0 | F8: 0 | G8: 0 | H8: 0
A9: 02:00-02:15 | B9: 0 | C9: 0 | D9: 0 | E9: 0 | F9: 0 | G9: 0 | H9: 0
A10: 02:15-02:30 | B10: 0 | C10: 0 | D10: 0 | E10: 0 | F10: 0 | G10: 0 | H10: 0
A11: 02:30-02:45 | B11: 0 | C11: 0 | D11: 0 | E11: 0 | F11: 0 | G11: 0 | H11: 0
A12: 02:45-03:00 | B12: 0 | C12: 0 | D12: 0 | E12: 0 | F12: 0 | G12: 0 | H12: 0
A13: 03:00-03:15 | B13: 0 | C13: 0 | D13: 0 | E13: 0 | F13: 0 | G13: 0 | H13: 0
... A96: 23:45-00:00 | B96: 0 | C96: 0 | D96: 0 | E96: 0 | F96: 0 | G96: 0 | H96: 0

Sheet Requisiti_psbo
A1: fasce | B1: Lun | C1: Mar | D1: Mer | E1: Gio | F1: Ven | G1: Sab | H1: Dom
A2: 00:15-00:30 | B2: 0 | C2: 0 | D2: 0 | E2: 0 | F2: 0 | G2: 0 | H2: 0
A3: 00:30-00:45 | B3: 0 | C3: 0 | D3: 0 | E3: 0 | F3: 0 | G3: 0 | H3: 0
A4: 00:45-01:00 | B4: 0 | C4: 0 | D4: 0 | E4: 0 | F4: 0 | G4: 0 | H4: 0
A5: 01:00-01:15 | B5: 0 | C5: 0 | D5: 0 | E5: 0 | F5: 0 | G5: 0 | H5: 0
A6: 01:15-01:30 | B6: 0 | C6: 0 | D6: 0 | E6: 0 | F6: 0 | G6: 0 | H6: 0
A7: 01:30-01:45 | B7: 0 | C7: 0 | D7: 0 | E7: 0 | F7: 0 | G7: 0 | H7: 0
A8: 01:45-02:00 | B8: 0 | C8: 0 | D8: 0 | E8: 0 | F8: 0 | G8: 0 | H8: 0
A9: 02:00-02:15 | B9: 0 | C9: 0 | D9: 0 | E9: 0 | F9: 0 | G9: 0 | H9: 0
A10: 02:15-02:30 | B10: 0 | C10: 0 | D10: 0 | E10: 0 | F10: 0 | G10: 0 | H10: 0
A11: 02:30-02:45 | B11: 0 | C11: 0 | D11: 0 | E11: 0 | F11: 0 | G11: 0 | H11: 0
A12: 02:45-03:00 | B12: 0 | C12: 0 | D12: 0 | E12: 0 | F12: 0 | G12: 0 | H12: 0
A13: 03:00-03:15 | B13: 0 | C13: 0 | D13: 0 | E13: 0 | F13: 0 | G13: 0 | H13: 0
... A96: 23:45-00:00 | B96: 0 | C96: 0 | D96: 0 | E96: 0 | F96: 0 | G96: 0 | H96: 0

Sheet Turni
A1: id turno | B1: entrata | C1: uscita | D1: Inzio spezzato | E1: Fine spezzato | F1: durata
A2: a1 | B2: 08:30 | C2: 12:30 | F2: 4
A3: a2 | B3: 08:30 | C3: 14:30 | F3: 6
A4: a3 | B4: 08:30 | C4: 0.52083333 | D4: 0.5625 | E4: 0.72916667 | F4: 8
A5: a4 | B5: 08:45 | C5: 12:45 | F5: 4
A6: a5 | B6: 08:45 | C6: 14:45 | F6: 6
A7: a6 | B7: 09:00 | C7: 13:00 | F7: 4
A8: a7 | B8: 09:00 | C8: 15:00 | F8: 6
A9: a8 | B9: 09:00 | C9: 0.54166667 | D9: 0.58333333 | E9: 0.75 | F9: 8
A10: a9 | B10: 09:15 | C10: 13:15 | F10: 4
A11: a10 | B11: 09:15 | C11: 15:15 | F11: 6
A12: a11 | B12: 09:30 | C12: 13:30 | F12: 4
A13: a12 | B13: 09:30 | C13: 15:30 | F13: 6
A14: a13 | B14: 09:30 | C14: 0.5625 | D14: 0.60416667 | E14: 0.77083333 | F14: 8
A15: a14 | B15: 09:45 | C15: 13:45 | F15: 4
A16: a15 | B16: 09:45 | C16: 15:45 | F16: 6
A17: a16 | B17: 10:00 | C17: 14:00 | F17: 4
A18: a17 | B18: 10:00 | C18: 16:00 | F18: 6
A19: a18 | B19: 10:00 | C19: 0.58333333 | D19: 0.625 | E19: 0.79166667 | F19: 8
A20: a19 | B20: 10:15 | C20: 14:15 | F20: 4
A21: a20 | B21: 10:15 | C21: 16:15 | F21: 6
A22: a21 | B22: 10:30 | C22: 14:30 | F22: 4
A23: a22 | B23: 10:30 | C23: 16:30 | F23: 6
A24: a23 | B24: 10:30 | C24: 0.60416667 | D24: 0.64583333 | E24: 0.8125 | F24: 8
A25: a24 | B25: 10:45 | C25: 14:45 | F25: 4
A26: a25 | B26: 10:45 | C26: 16:45 | F26: 6
A27: a26 | B27: 11:00 | C27: 15:00 | F27: 4
A28: a27 | B28: 11:00 | C28: 17:00 | F28: 6
A29: a28 | B29: 11:00 | C29: 0.625 | D29: 0.66666667 | E29: 0.83333333 | F29: 8
A30: a29 | B30: 11:15 | C30: 15:15 | F30: 4
A31: a30 | B31: 11:15 | C31: 17:15 | F31: 6
A32: a31 | B32: 11:30 | C32: 15:30 | F32: 4
A33: a32 | B33: 11:30 | C33: 17:30 | F33: 6
A34: a33 | B34: 11:30 | C34: 0.64583333 | D34: 0.6875 | E34: 0.85416667 | F34: 8
A35: a34 | B35: 11:45 | C35: 15:45 | F35: 4
A36: a35 | B36: 11:45 | C36: 17:45 | F36: 6
A37: a36 | B37: 12:00 | C37: 16:00 | F37: 4
A38: a37 | B38: 12:00 | C38: 18:00 | F38: 6
A39: a38 | B39: 12:00 | C39: 0.66666667 | D39: 0.70833333 | E39: 0.875 | F39: 8
A40: a39 | B40: 12:15 | C40: 16:15 | F40: 4
...

Sheet Risorse
A1: id dipendente | B1: Nome | C1: Ore | D1: Riposi | E1: Inizio fascia | F1: Fine fascia | G1: sabato | H1: domenica | I1: OT lun | J1: OT mar | K1: OT mer | L1: OT gio | M1: OT ven | N1: OT sab | O1: OT dom | P1: OT Spezz | Q1: combinazione | R1: fuori fascia | S1: skill | T1: inizio fascia lun | U1: fine fascia lun | V1: inizio fascia mar | W1: fine fascia mar | X1: inizio fascia mer | Y1: fine fascia mer | Z1: inizio fascia gio | AA1: fine fascia gio | AB1: inizio fascia ven | AC1: fine fascia ven | AD1: inizio fasica sab | AE1: fine fascia sab | AF1: inizio fascia dom | AG1: fine fascia dom | AH1: Riposo weekend suggerito | AI1: Sab lavorati (8w) | AJ1: Dom lavorate (8w) | AK1: Suggerimento lavoro WE | AL1: % Sab lavorati | AM1: % Dom lavorate | AN1: % Mattine | AO1: % Pomeriggi | AP1: % Sere | AQ1: WE doppi (Sab+Dom) | AR1: % WE doppi (Sab+Dom) | AS1: Seq Sab 0/1 (old?recent) | AT1: Seq Dom 0/1 (old?recent) | AU1: Sab lavorativi nel mese (ult. week) | AV1: Dom lavorative nel mese (ult. week) | AW1: >7 consecutivi (ult. 2w?) | AX1: Riposo da pianificare (prossima week)
A2: cf2 | B2: Ferranti Margherita | C2: 20 | D2: 2 | E2: 0.625 | F2: 0.875 | H2: Riposo | Q2: 4-4-4-4-4 | R2: 1 | S2: cmb | AH2: {=+IFERROR(_xlfn.XLOOKUP($B2,INDIRECT("'[storico profut.xlsm]Consiglio_Week'!$B:$B"),INDIRECT("'[storico profut.xlsm]Consiglio_Week'!$I:$I")),"")} | AI2: {=+IFERROR(_xlfn.XLOOKUP($B2,INDIRECT("'[storico profut.xlsm]Consiglio_Week'!$B:$B"),INDIRECT("'[storico profut.xlsm]Consiglio_Week'!$L:$L")),"")} | AJ2: {=+IFERROR(_xlfn.XLOOKUP($B2,INDIRECT("'[storico profut.xlsm]Consiglio_Week'!$B:$B"),INDIRECT("'[storico profut.xlsm]Consiglio_Week'!$M:$M")),"")} | AK2: {=+IFERROR(_xlfn.XLOOKUP($B2,INDIRECT("'[storico profut.xlsm]Consiglio_Week'!$B:$B"),INDIRECT("'[storico profut.xlsm]Consiglio_Week'!$P:$P")),"")} | AL2: {=IFERROR( _xlfn.XLOOKUP( $B2, INDIRECT("'[storico profut.xlsm]Consiglio_Week'!B:B"), OFFSET( INDIRECT("'[storico profut.xlsm]Consiglio_Week'!$R:$R"), 0, COLUMNS($A:A)-1 ) ), "" )} | AM2: {=IFERROR( _xlfn.XLOOKUP( $B2, INDIRECT("'[storico profut.xlsm]Consiglio_Week'!B:B"), OFFSET( INDIRECT("'[storico profut.xlsm]Consiglio_Week'!$R:$R"), 0, COLUMNS($A:B)-1 ) ), "" )} | AN2: {=IFERROR( _xlfn.XLOOKUP( $B2, INDIRECT("'[storico profut.xlsm]Consiglio_Week'!B:B"), OFFSET( INDIRECT("'[storico profut.xlsm]Consiglio_Week'!$R:$R"), 0, COLUMNS($A:C)-1 ) ), "" )} | AO2: {=IFERROR( _xlfn.XLOOKUP( $B2, INDIRECT("'[storico profut.xlsm]Consiglio_Week'!B:B"), OFFSET( INDIRECT("'[storico profut.xlsm]Consiglio_Week'!$R:$R"), 0, COLUMNS($A:D)-1 ) ), "" )} | AP2: {=IFERROR( _xlfn.XLOOKUP( $B2, INDIRECT("'[storico profut.xlsm]Consiglio_Week'!B:B"), OFFSET( INDIRECT("'[storico profut.xlsm]Consiglio_Week'!$R:$R"), 0, COLUMNS($A:E)-1 ) ), "" )} | AQ2: {=IFERROR( _xlfn.XLOOKUP( $B2, INDIRECT("'[storico profut.xlsm]Consiglio_Week'!B:B"), OFFSET( INDIRECT("'[storico profut.xlsm]Consiglio_Week'!$R:$R"), 0, COLUMNS($A:F)-1 ) ), "" )} | AR2: {=IFERROR( _xlfn.XLOOKUP( $B2, INDIRECT("'[storico profut.xlsm]Consiglio_Week'!B:B"), OFFSET( INDIRECT("'[storico profut.xlsm]Consiglio_Week'!$R:$R"), 0, COLUMNS($A:G)-1 ) ), "" )} | AS2: {=IFERROR( _xlfn.XLOOKUP( $B2, INDIRECT("'[storico profut.xlsm]Consiglio_Week'!B:B"), OFFSET( INDIRECT("'[storico profut.xlsm]Consiglio_Week'!$R:$R"), 0, COLUMNS($A:H)-1 ) ), "" )} | AT2: {=IFERROR( _xlfn.XLOOKUP( $B2, INDIRECT("'[storico profut.xlsm]Consiglio_Week'!B:B"), OFFSET( INDIRECT("'[storico profut.xlsm]Consiglio_Week'!$R:$R"), 0, COLUMNS($A:I)-1 ) ), "" )} | AU2: {=IFERROR( _xlfn.XLOOKUP( $B2, INDIRECT("'[storico profut.xlsm]Consiglio_Week'!B:B"), OFFSET( INDIRECT("'[storico profut.xlsm]Consiglio_Week'!$R:$R"), 0, COLUMNS($A:J)-1 ) ), "" )} | AV2: {=IFERROR( _xlfn.XLOOKUP( $B2, INDIRECT("'[storico profut.xlsm]Consiglio_Week'!B:B"), OFFSET( INDIRECT("'[storico profut.xlsm]Consiglio_Week'!$R:$R"), 0, COLUMNS($A:K)-1 ) ), "" )} | AW2: {=IFERROR( _xlfn.XLOOKUP( $B2, INDIRECT("'[storico profut.xlsm]Consiglio_Week'!B:B"), OFFSET( INDIRECT("'[storico profut.xlsm]Consiglio_Week'!$R:$R"), 0, COLUMNS($A:L)-1 ) ), "" )} | AX2: {=IFERROR( _xlfn.XLOOKUP( $B2, INDIRECT("'[storico profut.xlsm]Consiglio_Week'!B:B"), OFFSET( INDIRECT("'[storico profut.xlsm]Consiglio_Week'!$R:$R"), 0, COLUMNS($A:M)-1 ) ), "" )} | AY2: 0
A3: cf3 | B3: Inserra Maria Rita | C3: 20 | D3: 2 | E3: 0.625 | F3: 0.875 | H3: Riposo | Q3: 4-4-4-4-4 | R3: 1 | S3: cmb | AH3: {=+IFERROR(_xlfn.XLOOKUP($B3,INDIRECT("'[storico profut.xlsm]Consiglio_Week'!$B:$B"),INDIRECT("'[storico profut.xlsm]Consiglio_Week'!$I:$I")),"")} | AI3: {=+IFERROR(_xlfn.XLOOKUP($B3,INDIRECT("'[storico profut.xlsm]Consiglio_Week'!$B:$B"),INDIRECT("'[storico profut.xlsm]Consiglio_Week'!$L:$L")),"")} | AJ3: {=+IFERROR(_xlfn.XLOOKUP($B3,INDIRECT("'[storico profut.xlsm]Consiglio_Week'!$B:$B"),INDIRECT("'[storico profut.xlsm]Consiglio_Week'!$M:$M")),"")} | AK3: {=+IFERROR(_xlfn.XLOOKUP($B3,INDIRECT("'[storico profut.xlsm]Consiglio_Week'!$B:$B"),INDIRECT("'[storico profut.xlsm]Consiglio_Week'!$P:$P")),"")} | AL3: {=IFERROR( _xlfn.XLOOKUP( $B3, INDIRECT("'[storico profut.xlsm]Consiglio_Week'!B:B"), OFFSET( INDIRECT("'[storico profut.xlsm]Consiglio_Week'!$R:$R"), 0, COLUMNS($A:A)-1 ) ), "" )} | AM3: {=IFERROR( _xlfn.XLOOKUP( $B3, INDIRECT("'[storico profut.xlsm]Consiglio_Week'!B:B"), OFFSET( INDIRECT("'[storico profut.xlsm]Consiglio_Week'!$R:$R"), 0, COLUMNS($A:B)-1 ) ), "" )} | AN3: {=IFERROR( _xlfn.XLOOKUP( $B3, INDIRECT("'[storico profut.xlsm]Consiglio_Week'!B:B"), OFFSET( INDIRECT("'[storico profut.xlsm]Consiglio_Week'!$R:$R"), 0, COLUMNS($A:C)-1 ) ), "" )} | AO3: {=IFERROR( _xlfn.XLOOKUP( $B3, INDIRECT("'[storico profut.xlsm]Consiglio_Week'!B:B"), OFFSET( INDIRECT("'[storico profut.xlsm]Consiglio_Week'!$R:$R"), 0, COLUMNS($A:D)-1 ) ), "" )} | AP3: {=IFERROR( _xlfn.XLOOKUP( $B3, INDIRECT("'[storico profut.xlsm]Consiglio_Week'!B:B"), OFFSET( INDIRECT("'[storico profut.xlsm]Consiglio_Week'!$R:$R"), 0, COLUMNS($A:E)-1 ) ), "" )} | AQ3: {=IFERROR( _xlfn.XLOOKUP( $B3, INDIRECT("'[storico profut.xlsm]Consiglio_Week'!B:B"), OFFSET( INDIRECT("'[storico profut.xlsm]Consiglio_Week'!$R:$R"), 0, COLUMNS($A:F)-1 ) ), "" )} | AR3: {=IFERROR( _xlfn.XLOOKUP( $B3, INDIRECT("'[storico profut.xlsm]Consiglio_Week'!B:B"), OFFSET( INDIRECT("'[storico profut.xlsm]Consiglio_Week'!$R:$R"), 0, COLUMNS($A:G)-1 ) ), "" )} | AS3: {=IFERROR( _xlfn.XLOOKUP( $B3, INDIRECT("'[storico profut.xlsm]Consiglio_Week'!B:B"), OFFSET( INDIRECT("'[storico profut.xlsm]Consiglio_Week'!$R:$R"), 0, COLUMNS($A:H)-1 ) ), "" )} | AT3: {=IFERROR( _xlfn.XLOOKUP( $B3, INDIRECT("'[storico profut.xlsm]Consiglio_Week'!B:B"), OFFSET( INDIRECT("'[storico profut.xlsm]Consiglio_Week'!$R:$R"), 0, COLUMNS($A:I)-1 ) ), "" )} | AU3: {=IFERROR( _xlfn.XLOOKUP( $B3, INDIRECT("'[storico profut.xlsm]Consiglio_Week'!B:B"), OFFSET( INDIRECT("'[storico profut.xlsm]Consiglio_Week'!$R:$R"), 0, COLUMNS($A:J)-1 ) ), "" )} | AV3: {=IFERROR( _xlfn.XLOOKUP( $B3, INDIRECT("'[storico profut.xlsm]Consiglio_Week'!B:B"), OFFSET( INDIRECT("'[storico profut.xlsm]Consiglio_Week'!$R:$R"), 0, COLUMNS($A:K)-1 ) ), "" )} | AW3: {=IFERROR( _xlfn.XLOOKUP( $B3, INDIRECT("'[storico profut.xlsm]Consiglio_Week'!B:B"), OFFSET( INDIRECT("'[storico profut.xlsm]Consiglio_Week'!$R:$R"), 0, COLUMNS($A:L)-1 ) ), "" )} | AX3: {=IFERROR( _xlfn.XLOOKUP( $B3, INDIRECT("'[storico profut.xlsm]Consiglio_Week'!B:B"), OFFSET( INDIRECT("'[storico profut.xlsm]Consiglio_Week'!$R:$R"), 0, COLUMNS($A:M)-1 ) ), "" )} | AY3: 0
A4: cf6 | B4: Petta Vanessa | C4: 20 | D4: 2 | E4: 0.375 | F4: 0.625 | H4: Riposo | Q4: 4-4-4-4-4 | R4: 1 | S4: cmb | AH4: {=+IFERROR(_xlfn.XLOOKUP($B4,INDIRECT("'[storico profut.xlsm]Consiglio_Week'!$B:$B"),INDIRECT("'[storico profut.xlsm]Consiglio_Week'!$I:$I")),"")} | AI4: {=+IFERROR(_xlfn.XLOOKUP($B4,INDIRECT("'[storico profut.xlsm]Consiglio_Week'!$B:$B"),INDIRECT("'[storico profut.xlsm]Consiglio_Week'!$L:$L")),"")} | AJ4: {=+IFERROR(_xlfn.XLOOKUP($B4,INDIRECT("'[storico profut.xlsm]Consiglio_Week'!$B:$B"),INDIRECT("'[storico profut.xlsm]Consiglio_Week'!$M:$M")),"")} | AK4: {=+IFERROR(_xlfn.XLOOKUP($B4,INDIRECT("'[storico profut.xlsm]Consiglio_Week'!$B:$B"),INDIRECT("'[storico profut.xlsm]Consiglio_Week'!$P:$P")),"")} | AL4: {=IFERROR( _xlfn.XLOOKUP( $B4, INDIRECT("'[storico profut.xlsm]Consiglio_Week'!B:B"), OFFSET( INDIRECT("'[storico profut.xlsm]Consiglio_Week'!$R:$R"), 0, COLUMNS($A:A)-1 ) ), "" )} | AM4: {=IFERROR( _xlfn.XLOOKUP( $B4, INDIRECT("'[storico profut.xlsm]Consiglio_Week'!B:B"), OFFSET( INDIRECT("'[storico profut.xlsm]Consiglio_Week'!$R:$R"), 0, COLUMNS($A:B)-1 ) ), "" )} | AN4: {=IFERROR( _xlfn.XLOOKUP( $B4, INDIRECT("'[storico profut.xlsm]Consiglio_Week'!B:B"), OFFSET( INDIRECT("'[storico profut.xlsm]Consiglio_Week'!$R:$R"), 0, COLUMNS($A:C)-1 ) ), "" )} | AO4: {=IFERROR( _xlfn.XLOOKUP( $B4, INDIRECT("'[storico profut.xlsm]Consiglio_Week'!B:B"), OFFSET( INDIRECT("'[storico profut.xlsm]Consiglio_Week'!$R:$R"), 0, COLUMNS($A:D)-1 ) ), "" )} | AP4: {=IFERROR( _xlfn.XLOOKUP( $B4, INDIRECT("'[storico profut.xlsm]Consiglio_Week'!B:B"), OFFSET( INDIRECT("'[storico profut.xlsm]Consiglio_Week'!$R:$R"), 0, COLUMNS($A:E)-1 ) ), "" )} | AQ4: {=IFERROR( _xlfn.XLOOKUP( $B4, INDIRECT("'[storico profut.xlsm]Consiglio_Week'!B:B"), OFFSET( INDIRECT("'[storico profut.xlsm]Consiglio_Week'!$R:$R"), 0, COLUMNS($A:F)-1 ) ), "" )} | AR4: {=IFERROR( _xlfn.XLOOKUP( $B4, INDIRECT("'[storico profut.xlsm]Consiglio_Week'!B:B"), OFFSET( INDIRECT("'[storico profut.xlsm]Consiglio_Week'!$R:$R"), 0, COLUMNS($A:G)-1 ) ), "" )} | AS4: {=IFERROR( _xlfn.XLOOKUP( $B4, INDIRECT("'[storico profut.xlsm]Consiglio_Week'!B:B"), OFFSET( INDIRECT("'[storico profut.xlsm]Consiglio_Week'!$R:$R"), 0, COLUMNS($A:H)-1 ) ), "" )} | AT4: {=IFERROR( _xlfn.XLOOKUP( $B4, INDIRECT("'[storico profut.xlsm]Consiglio_Week'!B:B"), OFFSET( INDIRECT("'[storico profut.xlsm]Consiglio_Week'!$R:$R"), 0, COLUMNS($A:I)-1 ) ), "" )} | AU4: {=IFERROR( _xlfn.XLOOKUP( $B4, INDIRECT("'[storico profut.xlsm]Consiglio_Week'!B:B"), OFFSET( INDIRECT("'[storico profut.xlsm]Consiglio_Week'!$R:$R"), 0, COLUMNS($A:J)-1 ) ), "" )} | AV4: {=IFERROR( _xlfn.XLOOKUP( $B4, INDIRECT("'[storico profut.xlsm]Consiglio_Week'!B:B"), OFFSET( INDIRECT("'[storico profut.xlsm]Consiglio_Week'!$R:$R"), 0, COLUMNS($A:K)-1 ) ), "" )} | AW4: {=IFERROR( _xlfn.XLOOKUP( $B4, INDIRECT("'[storico profut.xlsm]Consiglio_Week'!B:B"), OFFSET( INDIRECT("'[storico profut.xlsm]Consiglio_Week'!$R:$R"), 0, COLUMNS($A:L)-1 ) ), "" )} | AX4: {=IFERROR( _xlfn.XLOOKUP( $B4, INDIRECT("'[storico profut.xlsm]Consiglio_Week'!B:B"), OFFSET( INDIRECT("'[storico profut.xlsm]Consiglio_Week'!$R:$R"), 0, COLUMNS($A:M)-1 ) ), "" )} | AY4: 0
A5: cf8 | B5: Sole Valentina | C5: 20 | D5: 2 | E5: 0.375 | F5: 0.625 | H5: Riposo | Q5: 4-4-4-4-4 | R5: 1 | S5: cmb | AH5: {=+IFERROR(_xlfn.XLOOKUP($B5,INDIRECT("'[storico profut.xlsm]Consiglio_Week'!$B:$B"),INDIRECT("'[storico profut.xlsm]Consiglio_Week'!$I:$I")),"")} | AI5: {=+IFERROR(_xlfn.XLOOKUP($B5,INDIRECT("'[storico profut.xlsm]Consiglio_Week'!$B:$B"),INDIRECT("'[storico profut.xlsm]Consiglio_Week'!$L:$L")),"")} | AJ5: {=+IFERROR(_xlfn.XLOOKUP($B5,INDIRECT("'[storico profut.xlsm]Consiglio_Week'!$B:$B"),INDIRECT("'[storico profut.xlsm]Consiglio_Week'!$M:$M")),"")} | AK5: {=+IFERROR(_xlfn.XLOOKUP($B5,INDIRECT("'[storico profut.xlsm]Consiglio_Week'!$B:$B"),INDIRECT("'[storico profut.xlsm]Consiglio_Week'!$P:$P")),"")} | AL5: {=IFERROR( _xlfn.XLOOKUP( $B5, INDIRECT("'[storico profut.xlsm]Consiglio_Week'!B:B"), OFFSET( INDIRECT("'[storico profut.xlsm]Consiglio_Week'!$R:$R"), 0, COLUMNS($A:A)-1 ) ), "" )} | AM5: {=IFERROR( _xlfn.XLOOKUP( $B5, INDIRECT("'[storico profut.xlsm]Consiglio_Week'!B:B"), OFFSET( INDIRECT("'[storico profut.xlsm]Consiglio_Week'!$R:$R"), 0, COLUMNS($A:B)-1 ) ), "" )} | AN5: {=IFERROR( _xlfn.XLOOKUP( $B5, INDIRECT("'[storico profut.xlsm]Consiglio_Week'!B:B"), OFFSET( INDIRECT("'[storico profut.xlsm]Consiglio_Week'!$R:$R"), 0, COLUMNS($A:C)-1 ) ), "" )} | AO5: {=IFERROR( _xlfn.XLOOKUP( $B5, INDIRECT("'[storico profut.xlsm]Consiglio_Week'!B:B"), OFFSET( INDIRECT("'[storico profut.xlsm]Consiglio_Week'!$R:$R"), 0, COLUMNS($A:D)-1 ) ), "" )} | AP5: {=IFERROR( _xlfn.XLOOKUP( $B5, INDIRECT("'[storico profut.xlsm]Consiglio_Week'!B:B"), OFFSET( INDIRECT("'[storico profut.xlsm]Consiglio_Week'!$R:$R"), 0, COLUMNS($A:E)-1 ) ), "" )} | AQ5: {=IFERROR( _xlfn.XLOOKUP( $B5, INDIRECT("'[storico profut.xlsm]Consiglio_Week'!B:B"), OFFSET( INDIRECT("'[storico profut.xlsm]Consiglio_Week'!$R:$R"), 0, COLUMNS($A:F)-1 ) ), "" )} | AR5: {=IFERROR( _xlfn.XLOOKUP( $B5, INDIRECT("'[storico profut.xlsm]Consiglio_Week'!B:B"), OFFSET( INDIRECT("'[storico profut.xlsm]Consiglio_Week'!$R:$R"), 0, COLUMNS($A:G)-1 ) ), "" )} | AS5: {=IFERROR( _xlfn.XLOOKUP( $B5, INDIRECT("'[storico profut.xlsm]Consiglio_Week'!B:B"), OFFSET( INDIRECT("'[storico profut.xlsm]Consiglio_Week'!$R:$R"), 0, COLUMNS($A:H)-1 ) ), "" )} | AT5: {=IFERROR( _xlfn.XLOOKUP( $B5, INDIRECT("'[storico profut.xlsm]Consiglio_Week'!B:B"), OFFSET( INDIRECT("'[storico profut.xlsm]Consiglio_Week'!$R:$R"), 0, COLUMNS($A:I)-1 ) ), "" )} | AU5: {=IFERROR( _xlfn.XLOOKUP( $B5, INDIRECT("'[storico profut.xlsm]Consiglio_Week'!B:B"), OFFSET( INDIRECT("'[storico profut.xlsm]Consiglio_Week'!$R:$R"), 0, COLUMNS($A:J)-1 ) ), "" )} | AV5: {=IFERROR( _xlfn.XLOOKUP( $B5, INDIRECT("'[storico profut.xlsm]Consiglio_Week'!B:B"), OFFSET( INDIRECT("'[storico profut.xlsm]Consiglio_Week'!$R:$R"), 0, COLUMNS($A:K)-1 ) ), "" )} | AW5: {=IFERROR( _xlfn.XLOOKUP( $B5, INDIRECT("'[storico profut.xlsm]Consiglio_Week'!B:B"), OFFSET( INDIRECT("'[storico profut.xlsm]Consiglio_Week'!$R:$R"), 0, COLUMNS($A:L)-1 ) ), "" )} | AX5: {=IFERROR( _xlfn.XLOOKUP( $B5, INDIRECT("'[storico profut.xlsm]Consiglio_Week'!B:B"), OFFSET( INDIRECT("'[storico profut.xlsm]Consiglio_Week'!$R:$R"), 0, COLUMNS($A:M)-1 ) ), "" )} | AY5: 0
A6: cf13 | B6: Albanese Carmelino | C6: 20 | D6: 2 | E6: 0.375 | F6: 0.625 | H6: Riposo | Q6: 4-4-4-4-4 | R6: 1 | S6: cmb | AH6: {=+IFERROR(_xlfn.XLOOKUP($B6,INDIRECT("'[storico profut.xlsm]Consiglio_Week'!$B:$B"),INDIRECT("'[storico profut.xlsm]Consiglio_Week'!$I:$I")),"")} | AI6: {=+IFERROR(_xlfn.XLOOKUP($B6,INDIRECT("'[storico profut.xlsm]Consiglio_Week'!$B:$B"),INDIRECT("'[storico profut.xlsm]Consiglio_Week'!$L:$L")),"")} | AJ6: {=+IFERROR(_xlfn.XLOOKUP($B6,INDIRECT("'[storico profut.xlsm]Consiglio_Week'!$B:$B"),INDIRECT("'[storico profut.xlsm]Consiglio_Week'!$M:$M")),"")} | AK6: {=+IFERROR(_xlfn.XLOOKUP($B6,INDIRECT("'[storico profut.xlsm]Consiglio_Week'!$B:$B"),INDIRECT("'[storico profut.xlsm]Consiglio_Week'!$P:$P")),"")} | AL6: {=IFERROR( _xlfn.XLOOKUP( $B6, INDIRECT("'[storico profut.xlsm]Consiglio_Week'!B:B"), OFFSET( INDIRECT("'[storico profut.xlsm]Consiglio_Week'!$R:$R"), 0, COLUMNS($A:A)-1 ) ), "" )} | AM6: {=IFERROR( _xlfn.XLOOKUP( $B6, INDIRECT("'[storico profut.xlsm]Consiglio_Week'!B:B"), OFFSET( INDIRECT("'[storico profut.xlsm]Consiglio_Week'!$R:$R"), 0, COLUMNS($A:B)-1 ) ), "" )} | AN6: {=IFERROR( _xlfn.XLOOKUP( $B6, INDIRECT("'[storico profut.xlsm]Consiglio_Week'!B:B"), OFFSET( INDIRECT("'[storico profut.xlsm]Consiglio_Week'!$R:$R"), 0, COLUMNS($A:C)-1 ) ), "" )} | AO6: {=IFERROR( _xlfn.XLOOKUP( $B6, INDIRECT("'[storico profut.xlsm]Consiglio_Week'!B:B"), OFFSET( INDIRECT("'[storico profut.xlsm]Consiglio_Week'!$R:$R"), 0, COLUMNS($A:D)-1 ) ), "" )} | AP6: {=IFERROR( _xlfn.XLOOKUP( $B6, INDIRECT("'[storico profut.xlsm]Consiglio_Week'!B:B"), OFFSET( INDIRECT("'[storico profut.xlsm]Consiglio_Week'!$R:$R"), 0, COLUMNS($A:E)-1 ) ), "" )} | AQ6: {=IFERROR( _xlfn.XLOOKUP( $B6, INDIRECT("'[storico profut.xlsm]Consiglio_Week'!B:B"), OFFSET( INDIRECT("'[storico profut.xlsm]Consiglio_Week'!$R:$R"), 0, COLUMNS($A:F)-1 ) ), "" )} | AR6: {=IFERROR( _xlfn.XLOOKUP( $B6, INDIRECT("'[storico profut.xlsm]Consiglio_Week'!B:B"), OFFSET( INDIRECT("'[storico profut.xlsm]Consiglio_Week'!$R:$R"), 0, COLUMNS($A:G)-1 ) ), "" )} | AS6: {=IFERROR( _xlfn.XLOOKUP( $B6, INDIRECT("'[storico profut.xlsm]Consiglio_Week'!B:B"), OFFSET( INDIRECT("'[storico profut.xlsm]Consiglio_Week'!$R:$R"), 0, COLUMNS($A:H)-1 ) ), "" )} | AT6: {=IFERROR( _xlfn.XLOOKUP( $B6, INDIRECT("'[storico profut.xlsm]Consiglio_Week'!B:B"), OFFSET( INDIRECT("'[storico profut.xlsm]Consiglio_Week'!$R:$R"), 0, COLUMNS($A:I)-1 ) ), "" )} | AU6: {=IFERROR( _xlfn.XLOOKUP( $B6, INDIRECT("'[storico profut.xlsm]Consiglio_Week'!B:B"), OFFSET( INDIRECT("'[storico profut.xlsm]Consiglio_Week'!$R:$R"), 0, COLUMNS($A:J)-1 ) ), "" )} | AV6: {=IFERROR( _xlfn.XLOOKUP( $B6, INDIRECT("'[storico profut.xlsm]Consiglio_Week'!B:B"), OFFSET( INDIRECT("'[storico profut.xlsm]Consiglio_Week'!$R:$R"), 0, COLUMNS($A:K)-1 ) ), "" )} | AW6: {=IFERROR( _xlfn.XLOOKUP( $B6, INDIRECT("'[storico profut.xlsm]Consiglio_Week'!B:B"), OFFSET( INDIRECT("'[storico profut.xlsm]Consiglio_Week'!$R:$R"), 0, COLUMNS($A:L)-1 ) ), "" )} | AX6: {=IFERROR( _xlfn.XLOOKUP( $B6, INDIRECT("'[storico profut.xlsm]Consiglio_Week'!B:B"), OFFSET( INDIRECT("'[storico profut.xlsm]Consiglio_Week'!$R:$R"), 0, COLUMNS($A:M)-1 ) ), "" )} | AY6: 0
A7: cf14 | B7: Borsellino Antonino | C7: 20 | D7: 2 | E7: 0.66666667 | F7: 0.83333333 | H7: Riposo | Q7: 4-4-4-4-4 | R7: 0 | S7: cmb | AH7: {=+IFERROR(_xlfn.XLOOKUP($B7,INDIRECT("'[storico profut.xlsm]Consiglio_Week'!$B:$B"),INDIRECT("'[storico profut.xlsm]Consiglio_Week'!$I:$I")),"")} | AI7: {=+IFERROR(_xlfn.XLOOKUP($B7,INDIRECT("'[storico profut.xlsm]Consiglio_Week'!$B:$B"),INDIRECT("'[storico profut.xlsm]Consiglio_Week'!$L:$L")),"")} | AJ7: {=+IFERROR(_xlfn.XLOOKUP($B7,INDIRECT("'[storico profut.xlsm]Consiglio_Week'!$B:$B"),INDIRECT("'[storico profut.xlsm]Consiglio_Week'!$M:$M")),"")} | AK7: {=+IFERROR(_xlfn.XLOOKUP($B7,INDIRECT("'[storico profut.xlsm]Consiglio_Week'!$B:$B"),INDIRECT("'[storico profut.xlsm]Consiglio_Week'!$P:$P")),"")} | AL7: {=IFERROR( _xlfn.XLOOKUP( $B7, INDIRECT("'[storico profut.xlsm]Consiglio_Week'!B:B"), OFFSET( INDIRECT("'[storico profut.xlsm]Consiglio_Week'!$R:$R"), 0, COLUMNS($A:A)-1 ) ), "" )} | AM7: {=IFERROR( _xlfn.XLOOKUP( $B7, INDIRECT("'[storico profut.xlsm]Consiglio_Week'!B:B"), OFFSET( INDIRECT("'[storico profut.xlsm]Consiglio_Week'!$R:$R"), 0, COLUMNS($A:B)-1 ) ), "" )} | AN7: {=IFERROR( _xlfn.XLOOKUP( $B7, INDIRECT("'[storico profut.xlsm]Consiglio_Week'!B:B"), OFFSET( INDIRECT("'[storico profut.xlsm]Consiglio_Week'!$R:$R"), 0, COLUMNS($A:C)-1 ) ), "" )} | AO7: {=IFERROR( _xlfn.XLOOKUP( $B7, INDIRECT("'[storico profut.xlsm]Consiglio_Week'!B:B"), OFFSET( INDIRECT("'[storico profut.xlsm]Consiglio_Week'!$R:$R"), 0, COLUMNS($A:D)-1 ) ), "" )} | AP7: {=IFERROR( _xlfn.XLOOKUP( $B7, INDIRECT("'[storico profut.xlsm]Consiglio_Week'!B:B"), OFFSET( INDIRECT("'[storico profut.xlsm]Consiglio_Week'!$R:$R"), 0, COLUMNS($A:E)-1 ) ), "" )} | AQ7: {=IFERROR( _xlfn.XLOOKUP( $B7, INDIRECT("'[storico profut.xlsm]Consiglio_Week'!B:B"), OFFSET( INDIRECT("'[storico profut.xlsm]Consiglio_Week'!$R:$R"), 0, COLUMNS($A:F)-1 ) ), "" )} | AR7: {=IFERROR( _xlfn.XLOOKUP( $B7, INDIRECT("'[storico profut.xlsm]Consiglio_Week'!B:B"), OFFSET( INDIRECT("'[storico profut.xlsm]Consiglio_Week'!$R:$R"), 0, COLUMNS($A:G)-1 ) ), "" )} | AS7: {=IFERROR( _xlfn.XLOOKUP( $B7, INDIRECT("'[storico profut.xlsm]Consiglio_Week'!B:B"), OFFSET( INDIRECT("'[storico profut.xlsm]Consiglio_Week'!$R:$R"), 0, COLUMNS($A:H)-1 ) ), "" )} | AT7: {=IFERROR( _xlfn.XLOOKUP( $B7, INDIRECT("'[storico profut.xlsm]Consiglio_Week'!B:B"), OFFSET( INDIRECT("'[storico profut.xlsm]Consiglio_Week'!$R:$R"), 0, COLUMNS($A:I)-1 ) ), "" )} | AU7: {=IFERROR( _xlfn.XLOOKUP( $B7, INDIRECT("'[storico profut.xlsm]Consiglio_Week'!B:B"), OFFSET( INDIRECT("'[storico profut.xlsm]Consiglio_Week'!$R:$R"), 0, COLUMNS($A:J)-1 ) ), "" )} | AV7: {=IFERROR( _xlfn.XLOOKUP( $B7, INDIRECT("'[storico profut.xlsm]Consiglio_Week'!B:B"), OFFSET( INDIRECT("'[storico profut.xlsm]Consiglio_Week'!$R:$R"), 0, COLUMNS($A:K)-1 ) ), "" )} | AW7: {=IFERROR( _xlfn.XLOOKUP( $B7, INDIRECT("'[storico profut.xlsm]Consiglio_Week'!B:B"), OFFSET( INDIRECT("'[storico profut.xlsm]Consiglio_Week'!$R:$R"), 0, COLUMNS($A:L)-1 ) ), "" )} | AX7: {=IFERROR( _xlfn.XLOOKUP( $B7, INDIRECT("'[storico profut.xlsm]Consiglio_Week'!B:B"), OFFSET( INDIRECT("'[storico profut.xlsm]Consiglio_Week'!$R:$R"), 0, COLUMNS($A:M)-1 ) ), "" )} | AY7: solo turno 16-20
A8: cf21 | B8: Burgio Rosa | C8: 20 | D8: 2 | E8: 0.625 | F8: 0.875 | H8: Riposo | Q8: 4-4-4-4-4 | R8: 1 | S8: cmb | AH8: {=+IFERROR(_xlfn.XLOOKUP($B8,INDIRECT("'[storico profut.xlsm]Consiglio_Week'!$B:$B"),INDIRECT("'[storico profut.xlsm]Consiglio_Week'!$I:$I")),"")} | AI8: {=+IFERROR(_xlfn.XLOOKUP($B8,INDIRECT("'[storico profut.xlsm]Consiglio_Week'!$B:$B"),INDIRECT("'[storico profut.xlsm]Consiglio_Week'!$L:$L")),"")} | AJ8: {=+IFERROR(_xlfn.XLOOKUP($B8,INDIRECT("'[storico profut.xlsm]Consiglio_Week'!$B:$B"),INDIRECT("'[storico profut.xlsm]Consiglio_Week'!$M:$M")),"")} | AK8: {=+IFERROR(_xlfn.XLOOKUP($B8,INDIRECT("'[storico profut.xlsm]Consiglio_Week'!$B:$B"),INDIRECT("'[storico profut.xlsm]Consiglio_Week'!$P:$P")),"")} | AL8: {=IFERROR( _xlfn.XLOOKUP( $B8, INDIRECT("'[storico profut.xlsm]Consiglio_Week'!B:B"), OFFSET( INDIRECT("'[storico profut.xlsm]Consiglio_Week'!$R:$R"), 0, COLUMNS($A:A)-1 ) ), "" )} | AM8: {=IFERROR( _xlfn.XLOOKUP( $B8, INDIRECT("'[storico profut.xlsm]Consiglio_Week'!B:B"), OFFSET( INDIRECT("'[storico profut.xlsm]Consiglio_Week'!$R:$R"), 0, COLUMNS($A:B)-1 ) ), "" )} | AN8: {=IFERROR( _xlfn.XLOOKUP( $B8, INDIRECT("'[storico profut.xlsm]Consiglio_Week'!B:B"), OFFSET( INDIRECT("'[storico profut.xlsm]Consiglio_Week'!$R:$R"), 0, COLUMNS($A:C)-1 ) ), "" )} | AO8: {=IFERROR( _xlfn.XLOOKUP( $B8, INDIRECT("'[storico profut.xlsm]Consiglio_Week'!B:B"), OFFSET( INDIRECT("'[storico profut.xlsm]Consiglio_Week'!$R:$R"), 0, COLUMNS($A:D)-1 ) ), "" )} | AP8: {=IFERROR( _xlfn.XLOOKUP( $B8, INDIRECT("'[storico profut.xlsm]Consiglio_Week'!B:B"), OFFSET( INDIRECT("'[storico profut.xlsm]Consiglio_Week'!$R:$R"), 0, COLUMNS($A:E)-1 ) ), "" )} | AQ8: {=IFERROR( _xlfn.XLOOKUP( $B8, INDIRECT("'[storico profut.xlsm]Consiglio_Week'!B:B"), OFFSET( INDIRECT("'[storico profut.xlsm]Consiglio_Week'!$R:$R"), 0, COLUMNS($A:F)-1 ) ), "" )} | AR8: {=IFERROR( _xlfn.XLOOKUP( $B8, INDIRECT("'[storico profut.xlsm]Consiglio_Week'!B:B"), OFFSET( INDIRECT("'[storico profut.xlsm]Consiglio_Week'!$R:$R"), 0, COLUMNS($A:G)-1 ) ), "" )} | AS8: {=IFERROR( _xlfn.XLOOKUP( $B8, INDIRECT("'[storico profut.xlsm]Consiglio_Week'!B:B"), OFFSET( INDIRECT("'[storico profut.xlsm]Consiglio_Week'!$R:$R"), 0, COLUMNS($A:H)-1 ) ), "" )} | AT8: {=IFERROR( _xlfn.XLOOKUP( $B8, INDIRECT("'[storico profut.xlsm]Consiglio_Week'!B:B"), OFFSET( INDIRECT("'[storico profut.xlsm]Consiglio_Week'!$R:$R"), 0, COLUMNS($A:I)-1 ) ), "" )} | AU8: {=IFERROR( _xlfn.XLOOKUP( $B8, INDIRECT("'[storico profut.xlsm]Consiglio_Week'!B:B"), OFFSET( INDIRECT("'[storico profut.xlsm]Consiglio_Week'!$R:$R"), 0, COLUMNS($A:J)-1 ) ), "" )} | AV8: {=IFERROR( _xlfn.XLOOKUP( $B8, INDIRECT("'[storico profut.xlsm]Consiglio_Week'!B:B"), OFFSET( INDIRECT("'[storico profut.xlsm]Consiglio_Week'!$R:$R"), 0, COLUMNS($A:K)-1 ) ), "" )} | AW8: {=IFERROR( _xlfn.XLOOKUP( $B8, INDIRECT("'[storico profut.xlsm]Consiglio_Week'!B:B"), OFFSET( INDIRECT("'[storico profut.xlsm]Consiglio_Week'!$R:$R"), 0, COLUMNS($A:L)-1 ) ), "" )} | AX8: {=IFERROR( _xlfn.XLOOKUP( $B8, INDIRECT("'[storico profut.xlsm]Consiglio_Week'!B:B"), OFFSET( INDIRECT("'[storico profut.xlsm]Consiglio_Week'!$R:$R"), 0, COLUMNS($A:M)-1 ) ), "" )} | AY8: 0
A9: cf23 | B9: Cannella Davide | C9: 20 | D9: 2 | E9: 0.375 | F9: 0.625 | H9: Riposo | Q9: 4-4-4-4-4 | R9: 1 | S9: cmb | AH9: {=+IFERROR(_xlfn.XLOOKUP($B9,INDIRECT("'[storico profut.xlsm]Consiglio_Week'!$B:$B"),INDIRECT("'[storico profut.xlsm]Consiglio_Week'!$I:$I")),"")} | AI9: {=+IFERROR(_xlfn.XLOOKUP($B9,INDIRECT("'[storico profut.xlsm]Consiglio_Week'!$B:$B"),INDIRECT("'[storico profut.xlsm]Consiglio_Week'!$L:$L")),"")} | AJ9: {=+IFERROR(_xlfn.XLOOKUP($B9,INDIRECT("'[storico profut.xlsm]Consiglio_Week'!$B:$B"),INDIRECT("'[storico profut.xlsm]Consiglio_Week'!$M:$M")),"")} | AK9: {=+IFERROR(_xlfn.XLOOKUP($B9,INDIRECT("'[storico profut.xlsm]Consiglio_Week'!$B:$B"),INDIRECT("'[storico profut.xlsm]Consiglio_Week'!$P:$P")),"")} | AL9: {=IFERROR( _xlfn.XLOOKUP( $B9, INDIRECT("'[storico profut.xlsm]Consiglio_Week'!B:B"), OFFSET( INDIRECT("'[storico profut.xlsm]Consiglio_Week'!$R:$R"), 0, COLUMNS($A:A)-1 ) ), "" )} | AM9: {=IFERROR( _xlfn.XLOOKUP( $B9, INDIRECT("'[storico profut.xlsm]Consiglio_Week'!B:B"), OFFSET( INDIRECT("'[storico profut.xlsm]Consiglio_Week'!$R:$R"), 0, COLUMNS($A:B)-1 ) ), "" )} | AN9: {=IFERROR( _xlfn.XLOOKUP( $B9, INDIRECT("'[storico profut.xlsm]Consiglio_Week'!B:B"), OFFSET( INDIRECT("'[storico profut.xlsm]Consiglio_Week'!$R:$R"), 0, COLUMNS($A:C)-1 ) ), "" )} | AO9: {=IFERROR( _xlfn.XLOOKUP( $B9, INDIRECT("'[storico profut.xlsm]Consiglio_Week'!B:B"), OFFSET( INDIRECT("'[storico profut.xlsm]Consiglio_Week'!$R:$R"), 0, COLUMNS($A:D)-1 ) ), "" )} | AP9: {=IFERROR( _xlfn.XLOOKUP( $B9, INDIRECT("'[storico profut.xlsm]Consiglio_Week'!B:B"), OFFSET( INDIRECT("'[storico profut.xlsm]Consiglio_Week'!$R:$R"), 0, COLUMNS($A:E)-1 ) ), "" )} | AQ9: {=IFERROR( _xlfn.XLOOKUP( $B9, INDIRECT("'[storico profut.xlsm]Consiglio_Week'!B:B"), OFFSET( INDIRECT("'[storico profut.xlsm]Consiglio_Week'!$R:$R"), 0, COLUMNS($A:F)-1 ) ), "" )} | AR9: {=IFERROR( _xlfn.XLOOKUP( $B9, INDIRECT("'[storico profut.xlsm]Consiglio_Week'!B:B"), OFFSET( INDIRECT("'[storico profut.xlsm]Consiglio_Week'!$R:$R"), 0, COLUMNS($A:G)-1 ) ), "" )} | AS9: {=IFERROR( _xlfn.XLOOKUP( $B9, INDIRECT("'[storico profut.xlsm]Consiglio_Week'!B:B"), OFFSET( INDIRECT("'[storico profut.xlsm]Consiglio_Week'!$R:$R"), 0, COLUMNS($A:H)-1 ) ), "" )} | AT9: {=IFERROR( _xlfn.XLOOKUP( $B9, INDIRECT("'[storico profut.xlsm]Consiglio_Week'!B:B"), OFFSET( INDIRECT("'[storico profut.xlsm]Consiglio_Week'!$R:$R"), 0, COLUMNS($A:I)-1 ) ), "" )} | AU9: {=IFERROR( _xlfn.XLOOKUP( $B9, INDIRECT("'[storico profut.xlsm]Consiglio_Week'!B:B"), OFFSET( INDIRECT("'[storico profut.xlsm]Consiglio_Week'!$R:$R"), 0, COLUMNS($A:J)-1 ) ), "" )} | AV9: {=IFERROR( _xlfn.XLOOKUP( $B9, INDIRECT("'[storico profut.xlsm]Consiglio_Week'!B:B"), OFFSET( INDIRECT("'[storico profut.xlsm]Consiglio_Week'!$R:$R"), 0, COLUMNS($A:K)-1 ) ), "" )} | AW9: {=IFERROR( _xlfn.XLOOKUP( $B9, INDIRECT("'[storico profut.xlsm]Consiglio_Week'!B:B"), OFFSET( INDIRECT("'[storico profut.xlsm]Consiglio_Week'!$R:$R"), 0, COLUMNS($A:L)-1 ) ), "" )} | AX9: {=IFERROR( _xlfn.XLOOKUP( $B9, INDIRECT("'[storico profut.xlsm]Consiglio_Week'!B:B"), OFFSET( INDIRECT("'[storico profut.xlsm]Consiglio_Week'!$R:$R"), 0, COLUMNS($A:M)-1 ) ), "" )} | AY9: turni opposti con moglie gibilaro
A10: cf26 | B10: Cipolla Giuseppe | C10: 20 | D10: 2 | E10: 0.625 | F10: 0.875 | H10: Riposo | Q10: 4-4-4-4-4 | R10: 1 | S10: cmb | AH10: {=+IFERROR(_xlfn.XLOOKUP($B10,INDIRECT("'[storico profut.xlsm]Consiglio_Week'!$B:$B"),INDIRECT("'[storico profut.xlsm]Consiglio_Week'!$I:$I")),"")} | AI10: {=+IFERROR(_xlfn.XLOOKUP($B10,INDIRECT("'[storico profut.xlsm]Consiglio_Week'!$B:$B"),INDIRECT("'[storico profut.xlsm]Consiglio_Week'!$L:$L")),"")} | AJ10: {=+IFERROR(_xlfn.XLOOKUP($B10,INDIRECT("'[storico profut.xlsm]Consiglio_Week'!$B:$B"),INDIRECT("'[storico profut.xlsm]Consiglio_Week'!$M:$M")),"")} | AK10: {=+IFERROR(_xlfn.XLOOKUP($B10,INDIRECT("'[storico profut.xlsm]Consiglio_Week'!$B:$B"),INDIRECT("'[storico profut.xlsm]Consiglio_Week'!$P:$P")),"")} | AL10: {=IFERROR( _xlfn.XLOOKUP( $B10, INDIRECT("'[storico profut.xlsm]Consiglio_Week'!B:B"), OFFSET( INDIRECT("'[storico profut.xlsm]Consiglio_Week'!$R:$R"), 0, COLUMNS($A:A)-1 ) ), "" )} | AM10: {=IFERROR( _xlfn.XLOOKUP( $B10, INDIRECT("'[storico profut.xlsm]Consiglio_Week'!B:B"), OFFSET( INDIRECT("'[storico profut.xlsm]Consiglio_Week'!$R:$R"), 0, COLUMNS($A:B)-1 ) ), "" )} | AN10: {=IFERROR( _xlfn.XLOOKUP( $B10, INDIRECT("'[storico profut.xlsm]Consiglio_Week'!B:B"), OFFSET( INDIRECT("'[storico profut.xlsm]Consiglio_Week'!$R:$R"), 0, COLUMNS($A:C)-1 ) ), "" )} | AO10: {=IFERROR( _xlfn.XLOOKUP( $B10, INDIRECT("'[storico profut.xlsm]Consiglio_Week'!B:B"), OFFSET( INDIRECT("'[storico profut.xlsm]Consiglio_Week'!$R:$R"), 0, COLUMNS($A:D)-1 ) ), "" )} | AP10: {=IFERROR( _xlfn.XLOOKUP( $B10, INDIRECT("'[storico profut.xlsm]Consiglio_Week'!B:B"), OFFSET( INDIRECT("'[storico profut.xlsm]Consiglio_Week'!$R:$R"), 0, COLUMNS($A:E)-1 ) ), "" )} | AQ10: {=IFERROR( _xlfn.XLOOKUP( $B10, INDIRECT("'[storico profut.xlsm]Consiglio_Week'!B:B"), OFFSET( INDIRECT("'[storico profut.xlsm]Consiglio_Week'!$R:$R"), 0, COLUMNS($A:F)-1 ) ), "" )} | AR10: {=IFERROR( _xlfn.XLOOKUP( $B10, INDIRECT("'[storico profut.xlsm]Consiglio_Week'!B:B"), OFFSET( INDIRECT("'[storico profut.xlsm]Consiglio_Week'!$R:$R"), 0, COLUMNS($A:G)-1 ) ), "" )} | AS10: {=IFERROR( _xlfn.XLOOKUP( $B10, INDIRECT("'[storico profut.xlsm]Consiglio_Week'!B:B"), OFFSET( INDIRECT("'[storico profut.xlsm]Consiglio_Week'!$R:$R"), 0, COLUMNS($A:H)-1 ) ), "" )} | AT10: {=IFERROR( _xlfn.XLOOKUP( $B10, INDIRECT("'[storico profut.xlsm]Consiglio_Week'!B:B"), OFFSET( INDIRECT("'[storico profut.xlsm]Consiglio_Week'!$R:$R"), 0, COLUMNS($A:I)-1 ) ), "" )} | AU10: {=IFERROR( _xlfn.XLOOKUP( $B10, INDIRECT("'[storico profut.xlsm]Consiglio_Week'!B:B"), OFFSET( INDIRECT("'[storico profut.xlsm]Consiglio_Week'!$R:$R"), 0, COLUMNS($A:J)-1 ) ), "" )} | AV10: {=IFERROR( _xlfn.XLOOKUP( $B10, INDIRECT("'[storico profut.xlsm]Consiglio_Week'!B:B"), OFFSET( INDIRECT("'[storico profut.xlsm]Consiglio_Week'!$R:$R"), 0, COLUMNS($A:K)-1 ) ), "" )} | AW10: {=IFERROR( _xlfn.XLOOKUP( $B10, INDIRECT("'[storico profut.xlsm]Consiglio_Week'!B:B"), OFFSET( INDIRECT("'[storico profut.xlsm]Consiglio_Week'!$R:$R"), 0, COLUMNS($A:L)-1 ) ), "" )} | AX10: {=IFERROR( _xlfn.XLOOKUP( $B10, INDIRECT("'[storico profut.xlsm]Consiglio_Week'!B:B"), OFFSET( INDIRECT("'[storico profut.xlsm]Consiglio_Week'!$R:$R"), 0, COLUMNS($A:M)-1 ) ), "" )} | AY10: 0
A11: cf30 | B11: Consentino Dario | C11: 20 | D11: 2 | E11: 0.58333333 | F11: 0.75 | H11: Riposo | Q11: 4-4-4-4-4 | R11: 0 | S11: cmb | AH11: {=+IFERROR(_xlfn.XLOOKUP($B11,INDIRECT("'[storico profut.xlsm]Consiglio_Week'!$B:$B"),INDIRECT("'[storico profut.xlsm]Consiglio_Week'!$I:$I")),"")} | AI11: {=+IFERROR(_xlfn.XLOOKUP($B11,INDIRECT("'[storico profut.xlsm]Consiglio_Week'!$B:$B"),INDIRECT("'[storico profut.xlsm]Consiglio_Week'!$L:$L")),"")} | AJ11: {=+IFERROR(_xlfn.XLOOKUP($B11,INDIRECT("'[storico profut.xlsm]Consiglio_Week'!$B:$B"),INDIRECT("'[storico profut.xlsm]Consiglio_Week'!$M:$M")),"")} | AK11: {=+IFERROR(_xlfn.XLOOKUP($B11,INDIRECT("'[storico profut.xlsm]Consiglio_Week'!$B:$B"),INDIRECT("'[storico profut.xlsm]Consiglio_Week'!$P:$P")),"")} | AL11: {=IFERROR( _xlfn.XLOOKUP( $B11, INDIRECT("'[storico profut.xlsm]Consiglio_Week'!B:B"), OFFSET( INDIRECT("'[storico profut.xlsm]Consiglio_Week'!$R:$R"), 0, COLUMNS($A:A)-1 ) ), "" )} | AM11: {=IFERROR( _xlfn.XLOOKUP( $B11, INDIRECT("'[storico profut.xlsm]Consiglio_Week'!B:B"), OFFSET( INDIRECT("'[storico profut.xlsm]Consiglio_Week'!$R:$R"), 0, COLUMNS($A:B)-1 ) ), "" )} | AN11: {=IFERROR( _xlfn.XLOOKUP( $B11, INDIRECT("'[storico profut.xlsm]Consiglio_Week'!B:B"), OFFSET( INDIRECT("'[storico profut.xlsm]Consiglio_Week'!$R:$R"), 0, COLUMNS($A:C)-1 ) ), "" )} | AO11: {=IFERROR( _xlfn.XLOOKUP( $B11, INDIRECT("'[storico profut.xlsm]Consiglio_Week'!B:B"), OFFSET( INDIRECT("'[storico profut.xlsm]Consiglio_Week'!$R:$R"), 0, COLUMNS($A:D)-1 ) ), "" )} | AP11: {=IFERROR( _xlfn.XLOOKUP( $B11, INDIRECT("'[storico profut.xlsm]Consiglio_Week'!B:B"), OFFSET( INDIRECT("'[storico profut.xlsm]Consiglio_Week'!$R:$R"), 0, COLUMNS($A:E)-1 ) ), "" )} | AQ11: {=IFERROR( _xlfn.XLOOKUP( $B11, INDIRECT("'[storico profut.xlsm]Consiglio_Week'!B:B"), OFFSET( INDIRECT("'[storico profut.xlsm]Consiglio_Week'!$R:$R"), 0, COLUMNS($A:F)-1 ) ), "" )} | AR11: {=IFERROR( _xlfn.XLOOKUP( $B11, INDIRECT("'[storico profut.xlsm]Consiglio_Week'!B:B"), OFFSET( INDIRECT("'[storico profut.xlsm]Consiglio_Week'!$R:$R"), 0, COLUMNS($A:G)-1 ) ), "" )} | AS11: {=IFERROR( _xlfn.XLOOKUP( $B11, INDIRECT("'[storico profut.xlsm]Consiglio_Week'!B:B"), OFFSET( INDIRECT("'[storico profut.xlsm]Consiglio_Week'!$R:$R"), 0, COLUMNS($A:H)-1 ) ), "" )} | AT11: {=IFERROR( _xlfn.XLOOKUP( $B11, INDIRECT("'[storico profut.xlsm]Consiglio_Week'!B:B"), OFFSET( INDIRECT("'[storico profut.xlsm]Consiglio_Week'!$R:$R"), 0, COLUMNS($A:I)-1 ) ), "" )} | AU11: {=IFERROR( _xlfn.XLOOKUP( $B11, INDIRECT("'[storico profut.xlsm]Consiglio_Week'!B:B"), OFFSET( INDIRECT("'[storico profut.xlsm]Consiglio_Week'!$R:$R"), 0, COLUMNS($A:J)-1 ) ), "" )} | AV11: {=IFERROR( _xlfn.XLOOKUP( $B11, INDIRECT("'[storico profut.xlsm]Consiglio_Week'!B:B"), OFFSET( INDIRECT("'[storico profut.xlsm]Consiglio_Week'!$R:$R"), 0, COLUMNS($A:K)-1 ) ), "" )} | AW11: {=IFERROR( _xlfn.XLOOKUP( $B11, INDIRECT("'[storico profut.xlsm]Consiglio_Week'!B:B"), OFFSET( INDIRECT("'[storico profut.xlsm]Consiglio_Week'!$R:$R"), 0, COLUMNS($A:L)-1 ) ), "" )} | AX11: {=IFERROR( _xlfn.XLOOKUP( $B11, INDIRECT("'[storico profut.xlsm]Consiglio_Week'!B:B"), OFFSET( INDIRECT("'[storico profut.xlsm]Consiglio_Week'!$R:$R"), 0, COLUMNS($A:M)-1 ) ), "" )} | AY11: blocco turno in questi orari 14:00-18:00,14:30-18:30 o 15:00-19:00
A12: cf34 | B12: D'acquisto Armida | C12: 20 | D12: 2 | E12: 0.375 | F12: 0.625 | H12: Riposo | Q12: 4-4-4-4-4 | R12: 1 | S12: cmb | AH12: {=+IFERROR(_xlfn.XLOOKUP($B12,INDIRECT("'[storico profut.xlsm]Consiglio_Week'!$B:$B"),INDIRECT("'[storico profut.xlsm]Consiglio_Week'!$I:$I")),"")} | AI12: {=+IFERROR(_xlfn.XLOOKUP($B12,INDIRECT("'[storico profut.xlsm]Consiglio_Week'!$B:$B"),INDIRECT("'[storico profut.xlsm]Consiglio_Week'!$L:$L")),"")} | AJ12: {=+IFERROR(_xlfn.XLOOKUP($B12,INDIRECT("'[storico profut.xlsm]Consiglio_Week'!$B:$B"),INDIRECT("'[storico profut.xlsm]Consiglio_Week'!$M:$M")),"")} | AK12: {=+IFERROR(_xlfn.XLOOKUP($B12,INDIRECT("'[storico profut.xlsm]Consiglio_Week'!$B:$B"),INDIRECT("'[storico profut.xlsm]Consiglio_Week'!$P:$P")),"")} | AL12: {=IFERROR( _xlfn.XLOOKUP( $B12, INDIRECT("'[storico profut.xlsm]Consiglio_Week'!B:B"), OFFSET( INDIRECT("'[storico profut.xlsm]Consiglio_Week'!$R:$R"), 0, COLUMNS($A:A)-1 ) ), "" )} | AM12: {=IFERROR( _xlfn.XLOOKUP( $B12, INDIRECT("'[storico profut.xlsm]Consiglio_Week'!B:B"), OFFSET( INDIRECT("'[storico profut.xlsm]Consiglio_Week'!$R:$R"), 0, COLUMNS($A:B)-1 ) ), "" )} | AN12: {=IFERROR( _xlfn.XLOOKUP( $B12, INDIRECT("'[storico profut.xlsm]Consiglio_Week'!B:B"), OFFSET( INDIRECT("'[storico profut.xlsm]Consiglio_Week'!$R:$R"), 0, COLUMNS($A:C)-1 ) ), "" )} | AO12: {=IFERROR( _xlfn.XLOOKUP( $B12, INDIRECT("'[storico profut.xlsm]Consiglio_Week'!B:B"), OFFSET( INDIRECT("'[storico profut.xlsm]Consiglio_Week'!$R:$R"), 0, COLUMNS($A:D)-1 ) ), "" )} | AP12: {=IFERROR( _xlfn.XLOOKUP( $B12, INDIRECT("'[storico profut.xlsm]Consiglio_Week'!B:B"), OFFSET( INDIRECT("'[storico profut.xlsm]Consiglio_Week'!$R:$R"), 0, COLUMNS($A:E)-1 ) ), "" )} | AQ12: {=IFERROR( _xlfn.XLOOKUP( $B12, INDIRECT("'[storico profut.xlsm]Consiglio_Week'!B:B"), OFFSET( INDIRECT("'[storico profut.xlsm]Consiglio_Week'!$R:$R"), 0, COLUMNS($A:F)-1 ) ), "" )} | AR12: {=IFERROR( _xlfn.XLOOKUP( $B12, INDIRECT("'[storico profut.xlsm]Consiglio_Week'!B:B"), OFFSET( INDIRECT("'[storico profut.xlsm]Consiglio_Week'!$R:$R"), 0, COLUMNS($A:G)-1 ) ), "" )} | AS12: {=IFERROR( _xlfn.XLOOKUP( $B12, INDIRECT("'[storico profut.xlsm]Consiglio_Week'!B:B"), OFFSET( INDIRECT("'[storico profut.xlsm]Consiglio_Week'!$R:$R"), 0, COLUMNS($A:H)-1 ) ), "" )} | AT12: {=IFERROR( _xlfn.XLOOKUP( $B12, INDIRECT("'[storico profut.xlsm]Consiglio_Week'!B:B"), OFFSET( INDIRECT("'[storico profut.xlsm]Consiglio_Week'!$R:$R"), 0, COLUMNS($A:I)-1 ) ), "" )} | AU12: {=IFERROR( _xlfn.XLOOKUP( $B12, INDIRECT("'[storico profut.xlsm]Consiglio_Week'!B:B"), OFFSET( INDIRECT("'[storico profut.xlsm]Consiglio_Week'!$R:$R"), 0, COLUMNS($A:J)-1 ) ), "" )} | AV12: {=IFERROR( _xlfn.XLOOKUP( $B12, INDIRECT("'[storico profut.xlsm]Consiglio_Week'!B:B"), OFFSET( INDIRECT("'[storico profut.xlsm]Consiglio_Week'!$R:$R"), 0, COLUMNS($A:K)-1 ) ), "" )} | AW12: {=IFERROR( _xlfn.XLOOKUP( $B12, INDIRECT("'[storico profut.xlsm]Consiglio_Week'!B:B"), OFFSET( INDIRECT("'[storico profut.xlsm]Consiglio_Week'!$R:$R"), 0, COLUMNS($A:L)-1 ) ), "" )} | AX12: {=IFERROR( _xlfn.XLOOKUP( $B12, INDIRECT("'[storico profut.xlsm]Consiglio_Week'!B:B"), OFFSET( INDIRECT("'[storico profut.xlsm]Consiglio_Week'!$R:$R"), 0, COLUMNS($A:M)-1 ) ), "" )} | AY12: 0
A13: cf38 | B13: Federico Filippo | C13: 21 | D13: 2 | E13: 0.625 | F13: 0.875 | H13: Riposo | Q13: 5-4-4-4-4 | R13: 1 | S13: cmb | AH13: {=+IFERROR(_xlfn.XLOOKUP($B13,INDIRECT("'[storico profut.xlsm]Consiglio_Week'!$B:$B"),INDIRECT("'[storico profut.xlsm]Consiglio_Week'!$I:$I")),"")} | AI13: {=+IFERROR(_xlfn.XLOOKUP($B13,INDIRECT("'[storico profut.xlsm]Consiglio_Week'!$B:$B"),INDIRECT("'[storico profut.xlsm]Consiglio_Week'!$L:$L")),"")} | AJ13: {=+IFERROR(_xlfn.XLOOKUP($B13,INDIRECT("'[storico profut.xlsm]Consiglio_Week'!$B:$B"),INDIRECT("'[storico profut.xlsm]Consiglio_Week'!$M:$M")),"")} | AK13: {=+IFERROR(_xlfn.XLOOKUP($B13,INDIRECT("'[storico profut.xlsm]Consiglio_Week'!$B:$B"),INDIRECT("'[storico profut.xlsm]Consiglio_Week'!$P:$P")),"")} | AL13: {=IFERROR( _xlfn.XLOOKUP( $B13, INDIRECT("'[storico profut.xlsm]Consiglio_Week'!B:B"), OFFSET( INDIRECT("'[storico profut.xlsm]Consiglio_Week'!$R:$R"), 0, COLUMNS($A:A)-1 ) ), "" )} | AM13: {=IFERROR( _xlfn.XLOOKUP( $B13, INDIRECT("'[storico profut.xlsm]Consiglio_Week'!B:B"), OFFSET( INDIRECT("'[storico profut.xlsm]Consiglio_Week'!$R:$R"), 0, COLUMNS($A:B)-1 ) ), "" )} | AN13: {=IFERROR( _xlfn.XLOOKUP( $B13, INDIRECT("'[storico profut.xlsm]Consiglio_Week'!B:B"), OFFSET( INDIRECT("'[storico profut.xlsm]Consiglio_Week'!$R:$R"), 0, COLUMNS($A:C)-1 ) ), "" )} | AO13: {=IFERROR( _xlfn.XLOOKUP( $B13, INDIRECT("'[storico profut.xlsm]Consiglio_Week'!B:B"), OFFSET( INDIRECT("'[storico profut.xlsm]Consiglio_Week'!$R:$R"), 0, COLUMNS($A:D)-1 ) ), "" )} | AP13: {=IFERROR( _xlfn.XLOOKUP( $B13, INDIRECT("'[storico profut.xlsm]Consiglio_Week'!B:B"), OFFSET( INDIRECT("'[storico profut.xlsm]Consiglio_Week'!$R:$R"), 0, COLUMNS($A:E)-1 ) ), "" )} | AQ13: {=IFERROR( _xlfn.XLOOKUP( $B13, INDIRECT("'[storico profut.xlsm]Consiglio_Week'!B:B"), OFFSET( INDIRECT("'[storico profut.xlsm]Consiglio_Week'!$R:$R"), 0, COLUMNS($A:F)-1 ) ), "" )} | AR13: {=IFERROR( _xlfn.XLOOKUP( $B13, INDIRECT("'[storico profut.xlsm]Consiglio_Week'!B:B"), OFFSET( INDIRECT("'[storico profut.xlsm]Consiglio_Week'!$R:$R"), 0, COLUMNS($A:G)-1 ) ), "" )} | AS13: {=IFERROR( _xlfn.XLOOKUP( $B13, INDIRECT("'[storico profut.xlsm]Consiglio_Week'!B:B"), OFFSET( INDIRECT("'[storico profut.xlsm]Consiglio_Week'!$R:$R"), 0, COLUMNS($A:H)-1 ) ), "" )} | AT13: {=IFERROR( _xlfn.XLOOKUP( $B13, INDIRECT("'[storico profut.xlsm]Consiglio_Week'!B:B"), OFFSET( INDIRECT("'[storico profut.xlsm]Consiglio_Week'!$R:$R"), 0, COLUMNS($A:I)-1 ) ), "" )} | AU13: {=IFERROR( _xlfn.XLOOKUP( $B13, INDIRECT("'[storico profut.xlsm]Consiglio_Week'!B:B"), OFFSET( INDIRECT("'[storico profut.xlsm]Consiglio_Week'!$R:$R"), 0, COLUMNS($A:J)-1 ) ), "" )} | AV13: {=IFERROR( _xlfn.XLOOKUP( $B13, INDIRECT("'[storico profut.xlsm]Consiglio_Week'!B:B"), OFFSET( INDIRECT("'[storico profut.xlsm]Consiglio_Week'!$R:$R"), 0, COLUMNS($A:K)-1 ) ), "" )} | AW13: {=IFERROR( _xlfn.XLOOKUP( $B13, INDIRECT("'[storico profut.xlsm]Consiglio_Week'!B:B"), OFFSET( INDIRECT("'[storico profut.xlsm]Consiglio_Week'!$R:$R"), 0, COLUMNS($A:L)-1 ) ), "" )} | AX13: {=IFERROR( _xlfn.XLOOKUP( $B13, INDIRECT("'[storico profut.xlsm]Consiglio_Week'!B:B"), OFFSET( INDIRECT("'[storico profut.xlsm]Consiglio_Week'!$R:$R"), 0, COLUMNS($A:M)-1 ) ), "" )} | AY13: 1gg a 5 ore
A14: cf40 | B14: Greco Loredana | C14: 20 | D14: 2 | E14: 0.625 | F14: 0.875 | H14: Riposo | Q14: 4-4-4-4-4 | R14: 1 | S14: cmb | AH14: {=+IFERROR(_xlfn.XLOOKUP($B14,INDIRECT("'[storico profut.xlsm]Consiglio_Week'!$B:$B"),INDIRECT("'[storico profut.xlsm]Consiglio_Week'!$I:$I")),"")} | AI14: {=+IFERROR(_xlfn.XLOOKUP($B14,INDIRECT("'[storico profut.xlsm]Consiglio_Week'!$B:$B"),INDIRECT("'[storico profut.xlsm]Consiglio_Week'!$L:$L")),"")} | AJ14: {=+IFERROR(_xlfn.XLOOKUP($B14,INDIRECT("'[storico profut.xlsm]Consiglio_Week'!$B:$B"),INDIRECT("'[storico profut.xlsm]Consiglio_Week'!$M:$M")),"")} | AK14: {=+IFERROR(_xlfn.XLOOKUP($B14,INDIRECT("'[storico profut.xlsm]Consiglio_Week'!$B:$B"),INDIRECT("'[storico profut.xlsm]Consiglio_Week'!$P:$P")),"")} | AL14: {=IFERROR( _xlfn.XLOOKUP( $B14, INDIRECT("'[storico profut.xlsm]Consiglio_Week'!B:B"), OFFSET( INDIRECT("'[storico profut.xlsm]Consiglio_Week'!$R:$R"), 0, COLUMNS($A:A)-1 ) ), "" )} | AM14: {=IFERROR( _xlfn.XLOOKUP( $B14, INDIRECT("'[storico profut.xlsm]Consiglio_Week'!B:B"), OFFSET( INDIRECT("'[storico profut.xlsm]Consiglio_Week'!$R:$R"), 0, COLUMNS($A:B)-1 ) ), "" )} | AN14: {=IFERROR( _xlfn.XLOOKUP( $B14, INDIRECT("'[storico profut.xlsm]Consiglio_Week'!B:B"), OFFSET( INDIRECT("'[storico profut.xlsm]Consiglio_Week'!$R:$R"), 0, COLUMNS($A:C)-1 ) ), "" )} | AO14: {=IFERROR( _xlfn.XLOOKUP( $B14, INDIRECT("'[storico profut.xlsm]Consiglio_Week'!B:B"), OFFSET( INDIRECT("'[storico profut.xlsm]Consiglio_Week'!$R:$R"), 0, COLUMNS($A:D)-1 ) ), "" )} | AP14: {=IFERROR( _xlfn.XLOOKUP( $B14, INDIRECT("'[storico profut.xlsm]Consiglio_Week'!B:B"), OFFSET( INDIRECT("'[storico profut.xlsm]Consiglio_Week'!$R:$R"), 0, COLUMNS($A:E)-1 ) ), "" )} | AQ14: {=IFERROR( _xlfn.XLOOKUP( $B14, INDIRECT("'[storico profut.xlsm]Consiglio_Week'!B:B"), OFFSET( INDIRECT("'[storico profut.xlsm]Consiglio_Week'!$R:$R"), 0, COLUMNS($A:F)-1 ) ), "" )} | AR14: {=IFERROR( _xlfn.XLOOKUP( $B14, INDIRECT("'[storico profut.xlsm]Consiglio_Week'!B:B"), OFFSET( INDIRECT("'[storico profut.xlsm]Consiglio_Week'!$R:$R"), 0, COLUMNS($A:G)-1 ) ), "" )} | AS14: {=IFERROR( _xlfn.XLOOKUP( $B14, INDIRECT("'[storico profut.xlsm]Consiglio_Week'!B:B"), OFFSET( INDIRECT("'[storico profut.xlsm]Consiglio_Week'!$R:$R"), 0, COLUMNS($A:H)-1 ) ), "" )} | AT14: {=IFERROR( _xlfn.XLOOKUP( $B14, INDIRECT("'[storico profut.xlsm]Consiglio_Week'!B:B"), OFFSET( INDIRECT("'[storico profut.xlsm]Consiglio_Week'!$R:$R"), 0, COLUMNS($A:I)-1 ) ), "" )} | AU14: {=IFERROR( _xlfn.XLOOKUP( $B14, INDIRECT("'[storico profut.xlsm]Consiglio_Week'!B:B"), OFFSET( INDIRECT("'[storico profut.xlsm]Consiglio_Week'!$R:$R"), 0, COLUMNS($A:J)-1 ) ), "" )} | AV14: {=IFERROR( _xlfn.XLOOKUP( $B14, INDIRECT("'[storico profut.xlsm]Consiglio_Week'!B:B"), OFFSET( INDIRECT("'[storico profut.xlsm]Consiglio_Week'!$R:$R"), 0, COLUMNS($A:K)-1 ) ), "" )} | AW14: {=IFERROR( _xlfn.XLOOKUP( $B14, INDIRECT("'[storico profut.xlsm]Consiglio_Week'!B:B"), OFFSET( INDIRECT("'[storico profut.xlsm]Consiglio_Week'!$R:$R"), 0, COLUMNS($A:L)-1 ) ), "" )} | AX14: {=IFERROR( _xlfn.XLOOKUP( $B14, INDIRECT("'[storico profut.xlsm]Consiglio_Week'!B:B"), OFFSET( INDIRECT("'[storico profut.xlsm]Consiglio_Week'!$R:$R"), 0, COLUMNS($A:M)-1 ) ), "" )} | AY14: 0
A15: cf41 | B15: Gullo Patrizia | C15: 20 | D15: 2 | E15: 0.625 | F15: 0.875 | H15: Riposo | Q15: 4-4-4-4-4 | R15: 1 | S15: cmb | AH15: {=+IFERROR(_xlfn.XLOOKUP($B15,INDIRECT("'[storico profut.xlsm]Consiglio_Week'!$B:$B"),INDIRECT("'[storico profut.xlsm]Consiglio_Week'!$I:$I")),"")} | AI15: {=+IFERROR(_xlfn.XLOOKUP($B15,INDIRECT("'[storico profut.xlsm]Consiglio_Week'!$B:$B"),INDIRECT("'[storico profut.xlsm]Consiglio_Week'!$L:$L")),"")} | AJ15: {=+IFERROR(_xlfn.XLOOKUP($B15,INDIRECT("'[storico profut.xlsm]Consiglio_Week'!$B:$B"),INDIRECT("'[storico profut.xlsm]Consiglio_Week'!$M:$M")),"")} | AK15: {=+IFERROR(_xlfn.XLOOKUP($B15,INDIRECT("'[storico profut.xlsm]Consiglio_Week'!$B:$B"),INDIRECT("'[storico profut.xlsm]Consiglio_Week'!$P:$P")),"")} | AL15: {=IFERROR( _xlfn.XLOOKUP( $B15, INDIRECT("'[storico profut.xlsm]Consiglio_Week'!B:B"), OFFSET( INDIRECT("'[storico profut.xlsm]Consiglio_Week'!$R:$R"), 0, COLUMNS($A:A)-1 ) ), "" )} | AM15: {=IFERROR( _xlfn.XLOOKUP( $B15, INDIRECT("'[storico profut.xlsm]Consiglio_Week'!B:B"), OFFSET( INDIRECT("'[storico profut.xlsm]Consiglio_Week'!$R:$R"), 0, COLUMNS($A:B)-1 ) ), "" )} | AN15: {=IFERROR( _xlfn.XLOOKUP( $B15, INDIRECT("'[storico profut.xlsm]Consiglio_Week'!B:B"), OFFSET( INDIRECT("'[storico profut.xlsm]Consiglio_Week'!$R:$R"), 0, COLUMNS($A:C)-1 ) ), "" )} | AO15: {=IFERROR( _xlfn.XLOOKUP( $B15, INDIRECT("'[storico profut.xlsm]Consiglio_Week'!B:B"), OFFSET( INDIRECT("'[storico profut.xlsm]Consiglio_Week'!$R:$R"), 0, COLUMNS($A:D)-1 ) ), "" )} | AP15: {=IFERROR( _xlfn.XLOOKUP( $B15, INDIRECT("'[storico profut.xlsm]Consiglio_Week'!B:B"), OFFSET( INDIRECT("'[storico profut.xlsm]Consiglio_Week'!$R:$R"), 0, COLUMNS($A:E)-1 ) ), "" )} | AQ15: {=IFERROR( _xlfn.XLOOKUP( $B15, INDIRECT("'[storico profut.xlsm]Consiglio_Week'!B:B"), OFFSET( INDIRECT("'[storico profut.xlsm]Consiglio_Week'!$R:$R"), 0, COLUMNS($A:F)-1 ) ), "" )} | AR15: {=IFERROR( _xlfn.XLOOKUP( $B15, INDIRECT("'[storico profut.xlsm]Consiglio_Week'!B:B"), OFFSET( INDIRECT("'[storico profut.xlsm]Consiglio_Week'!$R:$R"), 0, COLUMNS($A:G)-1 ) ), "" )} | AS15: {=IFERROR( _xlfn.XLOOKUP( $B15, INDIRECT("'[storico profut.xlsm]Consiglio_Week'!B:B"), OFFSET( INDIRECT("'[storico profut.xlsm]Consiglio_Week'!$R:$R"), 0, COLUMNS($A:H)-1 ) ), "" )} | AT15: {=IFERROR( _xlfn.XLOOKUP( $B15, INDIRECT("'[storico profut.xlsm]Consiglio_Week'!B:B"), OFFSET( INDIRECT("'[storico profut.xlsm]Consiglio_Week'!$R:$R"), 0, COLUMNS($A:I)-1 ) ), "" )} | AU15: {=IFERROR( _xlfn.XLOOKUP( $B15, INDIRECT("'[storico profut.xlsm]Consiglio_Week'!B:B"), OFFSET( INDIRECT("'[storico profut.xlsm]Consiglio_Week'!$R:$R"), 0, COLUMNS($A:J)-1 ) ), "" )} | AV15: {=IFERROR( _xlfn.XLOOKUP( $B15, INDIRECT("'[storico profut.xlsm]Consiglio_Week'!B:B"), OFFSET( INDIRECT("'[storico profut.xlsm]Consiglio_Week'!$R:$R"), 0, COLUMNS($A:K)-1 ) ), "" )} | AW15: {=IFERROR( _xlfn.XLOOKUP( $B15, INDIRECT("'[storico profut.xlsm]Consiglio_Week'!B:B"), OFFSET( INDIRECT("'[storico profut.xlsm]Consiglio_Week'!$R:$R"), 0, COLUMNS($A:L)-1 ) ), "" )} | AX15: {=IFERROR( _xlfn.XLOOKUP( $B15, INDIRECT("'[storico profut.xlsm]Consiglio_Week'!B:B"), OFFSET( INDIRECT("'[storico profut.xlsm]Consiglio_Week'!$R:$R"), 0, COLUMNS($A:M)-1 ) ), "" )} | AY15: 0
A16: cf42 | B16: Imparato Emanuele | C16: 20 | D16: 2 | E16: 0.375 | F16: 0.54166667 | H16: Riposo | Q16: 4-4-4-4-4 | R16: 0 | S16: cmb | AH16: {=+IFERROR(_xlfn.XLOOKUP($B16,INDIRECT("'[storico profut.xlsm]Consiglio_Week'!$B:$B"),INDIRECT("'[storico profut.xlsm]Consiglio_Week'!$I:$I")),"")} | AI16: {=+IFERROR(_xlfn.XLOOKUP($B16,INDIRECT("'[storico profut.xlsm]Consiglio_Week'!$B:$B"),INDIRECT("'[storico profut.xlsm]Consiglio_Week'!$L:$L")),"")} | AJ16: {=+IFERROR(_xlfn.XLOOKUP($B16,INDIRECT("'[storico profut.xlsm]Consiglio_Week'!$B:$B"),INDIRECT("'[storico profut.xlsm]Consiglio_Week'!$M:$M")),"")} | AK16: {=+IFERROR(_xlfn.XLOOKUP($B16,INDIRECT("'[storico profut.xlsm]Consiglio_Week'!$B:$B"),INDIRECT("'[storico profut.xlsm]Consiglio_Week'!$P:$P")),"")} | AL16: {=IFERROR( _xlfn.XLOOKUP( $B16, INDIRECT("'[storico profut.xlsm]Consiglio_Week'!B:B"), OFFSET( INDIRECT("'[storico profut.xlsm]Consiglio_Week'!$R:$R"), 0, COLUMNS($A:A)-1 ) ), "" )} | AM16: {=IFERROR( _xlfn.XLOOKUP( $B16, INDIRECT("'[storico profut.xlsm]Consiglio_Week'!B:B"), OFFSET( INDIRECT("'[storico profut.xlsm]Consiglio_Week'!$R:$R"), 0, COLUMNS($A:B)-1 ) ), "" )} | AN16: {=IFERROR( _xlfn.XLOOKUP( $B16, INDIRECT("'[storico profut.xlsm]Consiglio_Week'!B:B"), OFFSET( INDIRECT("'[storico profut.xlsm]Consiglio_Week'!$R:$R"), 0, COLUMNS($A:C)-1 ) ), "" )} | AO16: {=IFERROR( _xlfn.XLOOKUP( $B16, INDIRECT("'[storico profut.xlsm]Consiglio_Week'!B:B"), OFFSET( INDIRECT("'[storico profut.xlsm]Consiglio_Week'!$R:$R"), 0, COLUMNS($A:D)-1 ) ), "" )} | AP16: {=IFERROR( _xlfn.XLOOKUP( $B16, INDIRECT("'[storico profut.xlsm]Consiglio_Week'!B:B"), OFFSET( INDIRECT("'[storico profut.xlsm]Consiglio_Week'!$R:$R"), 0, COLUMNS($A:E)-1 ) ), "" )} | AQ16: {=IFERROR( _xlfn.XLOOKUP( $B16, INDIRECT("'[storico profut.xlsm]Consiglio_Week'!B:B"), OFFSET( INDIRECT("'[storico profut.xlsm]Consiglio_Week'!$R:$R"), 0, COLUMNS($A:F)-1 ) ), "" )} | AR16: {=IFERROR( _xlfn.XLOOKUP( $B16, INDIRECT("'[storico profut.xlsm]Consiglio_Week'!B:B"), OFFSET( INDIRECT("'[storico profut.xlsm]Consiglio_Week'!$R:$R"), 0, COLUMNS($A:G)-1 ) ), "" )} | AS16: {=IFERROR( _xlfn.XLOOKUP( $B16, INDIRECT("'[storico profut.xlsm]Consiglio_Week'!B:B"), OFFSET( INDIRECT("'[storico profut.xlsm]Consiglio_Week'!$R:$R"), 0, COLUMNS($A:H)-1 ) ), "" )} | AT16: {=IFERROR( _xlfn.XLOOKUP( $B16, INDIRECT("'[storico profut.xlsm]Consiglio_Week'!B:B"), OFFSET( INDIRECT("'[storico profut.xlsm]Consiglio_Week'!$R:$R"), 0, COLUMNS($A:I)-1 ) ), "" )} | AU16: {=IFERROR( _xlfn.XLOOKUP( $B16, INDIRECT("'[storico profut.xlsm]Consiglio_Week'!B:B"), OFFSET( INDIRECT("'[storico profut.xlsm]Consiglio_Week'!$R:$R"), 0, COLUMNS($A:J)-1 ) ), "" )} | AV16: {=IFERROR( _xlfn.XLOOKUP( $B16, INDIRECT("'[storico profut.xlsm]Consiglio_Week'!B:B"), OFFSET( INDIRECT("'[storico profut.xlsm]Consiglio_Week'!$R:$R"), 0, COLUMNS($A:K)-1 ) ), "" )} | AW16: {=IFERROR( _xlfn.XLOOKUP( $B16, INDIRECT("'[storico profut.xlsm]Consiglio_Week'!B:B"), OFFSET( INDIRECT("'[storico profut.xlsm]Consiglio_Week'!$R:$R"), 0, COLUMNS($A:L)-1 ) ), "" )} | AX16: {=IFERROR( _xlfn.XLOOKUP( $B16, INDIRECT("'[storico profut.xlsm]Consiglio_Week'!B:B"), OFFSET( INDIRECT("'[storico profut.xlsm]Consiglio_Week'!$R:$R"), 0, COLUMNS($A:M)-1 ) ), "" )} | AY16: blocco turno 9-13
A17: cf43 | B17: Mancuso Vito | C17: 20 | D17: 2 | E17: 0.625 | F17: 0.875 | H17: Riposo | Q17: 4-4-4-4-4 | R17: 1 | S17: cmb | AH17: {=+IFERROR(_xlfn.XLOOKUP($B17,INDIRECT("'[storico profut.xlsm]Consiglio_Week'!$B:$B"),INDIRECT("'[storico profut.xlsm]Consiglio_Week'!$I:$I")),"")} | AI17: {=+IFERROR(_xlfn.XLOOKUP($B17,INDIRECT("'[storico profut.xlsm]Consiglio_Week'!$B:$B"),INDIRECT("'[storico profut.xlsm]Consiglio_Week'!$L:$L")),"")} | AJ17: {=+IFERROR(_xlfn.XLOOKUP($B17,INDIRECT("'[storico profut.xlsm]Consiglio_Week'!$B:$B"),INDIRECT("'[storico profut.xlsm]Consiglio_Week'!$M:$M")),"")} | AK17: {=+IFERROR(_xlfn.XLOOKUP($B17,INDIRECT("'[storico profut.xlsm]Consiglio_Week'!$B:$B"),INDIRECT("'[storico profut.xlsm]Consiglio_Week'!$P:$P")),"")} | AL17: {=IFERROR( _xlfn.XLOOKUP( $B17, INDIRECT("'[storico profut.xlsm]Consiglio_Week'!B:B"), OFFSET( INDIRECT("'[storico profut.xlsm]Consiglio_Week'!$R:$R"), 0, COLUMNS($A:A)-1 ) ), "" )} | AM17: {=IFERROR( _xlfn.XLOOKUP( $B17, INDIRECT("'[storico profut.xlsm]Consiglio_Week'!B:B"), OFFSET( INDIRECT("'[storico profut.xlsm]Consiglio_Week'!$R:$R"), 0, COLUMNS($A:B)-1 ) ), "" )} | AN17: {=IFERROR( _xlfn.XLOOKUP( $B17, INDIRECT("'[storico profut.xlsm]Consiglio_Week'!B:B"), OFFSET( INDIRECT("'[storico profut.xlsm]Consiglio_Week'!$R:$R"), 0, COLUMNS($A:C)-1 ) ), "" )} | AO17: {=IFERROR( _xlfn.XLOOKUP( $B17, INDIRECT("'[storico profut.xlsm]Consiglio_Week'!B:B"), OFFSET( INDIRECT("'[storico profut.xlsm]Consiglio_Week'!$R:$R"), 0, COLUMNS($A:D)-1 ) ), "" )} | AP17: {=IFERROR( _xlfn.XLOOKUP( $B17, INDIRECT("'[storico profut.xlsm]Consiglio_Week'!B:B"), OFFSET( INDIRECT("'[storico profut.xlsm]Consiglio_Week'!$R:$R"), 0, COLUMNS($A:E)-1 ) ), "" )} | AQ17: {=IFERROR( _xlfn.XLOOKUP( $B17, INDIRECT("'[storico profut.xlsm]Consiglio_Week'!B:B"), OFFSET( INDIRECT("'[storico profut.xlsm]Consiglio_Week'!$R:$R"), 0, COLUMNS($A:F)-1 ) ), "" )} | AR17: {=IFERROR( _xlfn.XLOOKUP( $B17, INDIRECT("'[storico profut.xlsm]Consiglio_Week'!B:B"), OFFSET( INDIRECT("'[storico profut.xlsm]Consiglio_Week'!$R:$R"), 0, COLUMNS($A:G)-1 ) ), "" )} | AS17: {=IFERROR( _xlfn.XLOOKUP( $B17, INDIRECT("'[storico profut.xlsm]Consiglio_Week'!B:B"), OFFSET( INDIRECT("'[storico profut.xlsm]Consiglio_Week'!$R:$R"), 0, COLUMNS($A:H)-1 ) ), "" )} | AT17: {=IFERROR( _xlfn.XLOOKUP( $B17, INDIRECT("'[storico profut.xlsm]Consiglio_Week'!B:B"), OFFSET( INDIRECT("'[storico profut.xlsm]Consiglio_Week'!$R:$R"), 0, COLUMNS($A:I)-1 ) ), "" )} | AU17: {=IFERROR( _xlfn.XLOOKUP( $B17, INDIRECT("'[storico profut.xlsm]Consiglio_Week'!B:B"), OFFSET( INDIRECT("'[storico profut.xlsm]Consiglio_Week'!$R:$R"), 0, COLUMNS($A:J)-1 ) ), "" )} | AV17: {=IFERROR( _xlfn.XLOOKUP( $B17, INDIRECT("'[storico profut.xlsm]Consiglio_Week'!B:B"), OFFSET( INDIRECT("'[storico profut.xlsm]Consiglio_Week'!$R:$R"), 0, COLUMNS($A:K)-1 ) ), "" )} | AW17: {=IFERROR( _xlfn.XLOOKUP( $B17, INDIRECT("'[storico profut.xlsm]Consiglio_Week'!B:B"), OFFSET( INDIRECT("'[storico profut.xlsm]Consiglio_Week'!$R:$R"), 0, COLUMNS($A:L)-1 ) ), "" )} | AX17: {=IFERROR( _xlfn.XLOOKUP( $B17, INDIRECT("'[storico profut.xlsm]Consiglio_Week'!B:B"), OFFSET( INDIRECT("'[storico profut.xlsm]Consiglio_Week'!$R:$R"), 0, COLUMNS($A:M)-1 ) ), "" )} | AY17: 0
